{
 "cells": [
  {
   "cell_type": "code",
   "execution_count": 9,
   "metadata": {
    "collapsed": true
   },
   "outputs": [],
   "source": [
    "# Dependencies\n",
    "import matplotlib.pyplot as plt\n",
    "import pandas as pd\n",
    "import numpy as np"
   ]
  },
  {
   "cell_type": "code",
   "execution_count": 10,
   "metadata": {},
   "outputs": [
    {
     "name": "stderr",
     "output_type": "stream",
     "text": [
      "ERROR:root:Internal Python error in the inspect module.\n",
      "Below is the traceback from this internal error.\n",
      "\n"
     ]
    },
    {
     "name": "stdout",
     "output_type": "stream",
     "text": [
      "Traceback (most recent call last):\n",
      "  File \"/Users/melissa/anaconda3/lib/python3.6/site-packages/IPython/core/interactiveshell.py\", line 2862, in run_code\n",
      "    exec(code_obj, self.user_global_ns, self.user_ns)\n",
      "  File \"<ipython-input-10-40bab5a302b2>\", line 5, in <module>\n",
      "    f_data=pd.read_csv(fdata)\n",
      "  File \"/Users/melissa/anaconda3/lib/python3.6/site-packages/pandas/io/parsers.py\", line 655, in parser_f\n",
      "    return _read(filepath_or_buffer, kwds)\n",
      "  File \"/Users/melissa/anaconda3/lib/python3.6/site-packages/pandas/io/parsers.py\", line 405, in _read\n",
      "    parser = TextFileReader(filepath_or_buffer, **kwds)\n",
      "  File \"/Users/melissa/anaconda3/lib/python3.6/site-packages/pandas/io/parsers.py\", line 764, in __init__\n",
      "    self._make_engine(self.engine)\n",
      "  File \"/Users/melissa/anaconda3/lib/python3.6/site-packages/pandas/io/parsers.py\", line 985, in _make_engine\n",
      "    self._engine = CParserWrapper(self.f, **self.options)\n",
      "  File \"/Users/melissa/anaconda3/lib/python3.6/site-packages/pandas/io/parsers.py\", line 1605, in __init__\n",
      "    self._reader = parsers.TextReader(src, **kwds)\n",
      "  File \"pandas/_libs/parsers.pyx\", line 394, in pandas._libs.parsers.TextReader.__cinit__ (pandas/_libs/parsers.c:4209)\n",
      "  File \"pandas/_libs/parsers.pyx\", line 710, in pandas._libs.parsers.TextReader._setup_parser_source (pandas/_libs/parsers.c:8873)\n",
      "FileNotFoundError: File b'/Raw_Data/FakeDataSet.csv' does not exist\n",
      "\n",
      "During handling of the above exception, another exception occurred:\n",
      "\n",
      "Traceback (most recent call last):\n",
      "  File \"/Users/melissa/anaconda3/lib/python3.6/site-packages/IPython/core/interactiveshell.py\", line 1806, in showtraceback\n",
      "    stb = value._render_traceback_()\n",
      "AttributeError: 'FileNotFoundError' object has no attribute '_render_traceback_'\n",
      "\n",
      "During handling of the above exception, another exception occurred:\n",
      "\n",
      "Traceback (most recent call last):\n",
      "  File \"/Users/melissa/anaconda3/lib/python3.6/site-packages/IPython/core/ultratb.py\", line 1090, in get_records\n",
      "    return _fixed_getinnerframes(etb, number_of_lines_of_context, tb_offset)\n",
      "  File \"/Users/melissa/anaconda3/lib/python3.6/site-packages/IPython/core/ultratb.py\", line 311, in wrapped\n",
      "    return f(*args, **kwargs)\n",
      "  File \"/Users/melissa/anaconda3/lib/python3.6/site-packages/IPython/core/ultratb.py\", line 345, in _fixed_getinnerframes\n",
      "    records = fix_frame_records_filenames(inspect.getinnerframes(etb, context))\n",
      "  File \"/Users/melissa/anaconda3/lib/python3.6/inspect.py\", line 1480, in getinnerframes\n",
      "    frameinfo = (tb.tb_frame,) + getframeinfo(tb, context)\n",
      "  File \"/Users/melissa/anaconda3/lib/python3.6/inspect.py\", line 1438, in getframeinfo\n",
      "    filename = getsourcefile(frame) or getfile(frame)\n",
      "  File \"/Users/melissa/anaconda3/lib/python3.6/inspect.py\", line 693, in getsourcefile\n",
      "    if getattr(getmodule(object, filename), '__loader__', None) is not None:\n",
      "  File \"/Users/melissa/anaconda3/lib/python3.6/inspect.py\", line 722, in getmodule\n",
      "    file = getabsfile(object, _filename)\n",
      "  File \"/Users/melissa/anaconda3/lib/python3.6/inspect.py\", line 706, in getabsfile\n",
      "    return os.path.normcase(os.path.abspath(_filename))\n",
      "  File \"/Users/melissa/anaconda3/lib/python3.6/posixpath.py\", line 374, in abspath\n",
      "    cwd = os.getcwd()\n",
      "FileNotFoundError: [Errno 2] No such file or directory\n"
     ]
    },
    {
     "ename": "FileNotFoundError",
     "evalue": "File b'/Raw_Data/FakeDataSet.csv' does not exist",
     "output_type": "error",
     "traceback": [
      "\u001b[0;31m---------------------------------------------------------------------------\u001b[0m"
     ]
    }
   ],
   "source": [
    "# File to load\n",
    "fdata=\"Raw_Data/FakeDataSet.csv\"\n",
    "\n",
    "# Read the Data\n",
    "f_data=pd.read_csv(fdata)\n",
    "f_data.head()"
   ]
  },
  {
   "cell_type": "code",
   "execution_count": null,
   "metadata": {
    "collapsed": true
   },
   "outputs": [],
   "source": []
  }
 ],
 "metadata": {
  "kernelspec": {
   "display_name": "Python 3",
   "language": "python",
   "name": "python3"
  },
  "language_info": {
   "codemirror_mode": {
    "name": "ipython",
    "version": 3
   },
   "file_extension": ".py",
   "mimetype": "text/x-python",
   "name": "python",
   "nbconvert_exporter": "python",
   "pygments_lexer": "ipython3",
   "version": "3.6.3"
  }
 },
 "nbformat": 4,
 "nbformat_minor": 2
}
